[2024-10-08T09:08:08.075+0000] {local_task_job_runner.py:123} INFO - ::group::Pre task execution logs
[2024-10-08T09:08:08.188+0000] {taskinstance.py:2612} INFO - Dependencies all met for dep_context=non-requeueable deps ti=<TaskInstance: spotify_etl_dag.move_processed_data manual__2024-10-08T09:06:50.168917+00:00 [queued]>
[2024-10-08T09:08:08.207+0000] {taskinstance.py:2612} INFO - Dependencies all met for dep_context=requeueable deps ti=<TaskInstance: spotify_etl_dag.move_processed_data manual__2024-10-08T09:06:50.168917+00:00 [queued]>
[2024-10-08T09:08:08.208+0000] {taskinstance.py:2865} INFO - Starting attempt 1 of 1
[2024-10-08T09:08:08.269+0000] {taskinstance.py:2888} INFO - Executing <Task(PythonOperator): move_processed_data> on 2024-10-08 09:06:50.168917+00:00
[2024-10-08T09:08:08.317+0000] {standard_task_runner.py:104} INFO - Running: ['***', 'tasks', 'run', 'spotify_etl_dag', 'move_processed_data', 'manual__2024-10-08T09:06:50.168917+00:00', '--job-id', '445', '--raw', '--subdir', 'DAGS_FOLDER/spotify_***_pipeline.py', '--cfg-path', '/tmp/tmpeo1c2bz9']
[2024-10-08T09:08:08.321+0000] {standard_task_runner.py:105} INFO - Job 445: Subtask move_processed_data
[2024-10-08T09:08:08.318+0000] {warnings.py:112} WARNING - /home/***/.local/lib/python3.12/site-packages/***/task/task_runner/standard_task_runner.py:70: DeprecationWarning: This process (pid=892) is multi-threaded, use of fork() may lead to deadlocks in the child.
  pid = os.fork()

[2024-10-08T09:08:08.327+0000] {standard_task_runner.py:72} INFO - Started process 894 to run task
[2024-10-08T09:08:08.645+0000] {task_command.py:467} INFO - Running <TaskInstance: spotify_etl_dag.move_processed_data manual__2024-10-08T09:06:50.168917+00:00 [running]> on host da4c4a711107
[2024-10-08T09:08:09.072+0000] {taskinstance.py:3131} INFO - Exporting env vars: AIRFLOW_CTX_DAG_OWNER='Artika' AIRFLOW_CTX_DAG_ID='spotify_etl_dag' AIRFLOW_CTX_TASK_ID='move_processed_data' AIRFLOW_CTX_EXECUTION_DATE='2024-10-08T09:06:50.168917+00:00' AIRFLOW_CTX_TRY_NUMBER='1' AIRFLOW_CTX_DAG_RUN_ID='manual__2024-10-08T09:06:50.168917+00:00'
[2024-10-08T09:08:09.082+0000] {logging_mixin.py:190} INFO - Task instance is in running state
[2024-10-08T09:08:09.082+0000] {logging_mixin.py:190} INFO -  Previous state of the Task instance: queued
[2024-10-08T09:08:09.083+0000] {logging_mixin.py:190} INFO - Current task name:move_processed_data state:running start_date:2024-10-08 09:08:08.189921+00:00
[2024-10-08T09:08:09.084+0000] {logging_mixin.py:190} INFO - Dag name:spotify_etl_dag and current dag run status:running
[2024-10-08T09:08:09.085+0000] {taskinstance.py:731} INFO - ::endgroup::
[2024-10-08T09:08:09.087+0000] {taskinstance.py:3310} ERROR - Task failed with exception
Traceback (most recent call last):
  File "/home/airflow/.local/lib/python3.12/site-packages/airflow/models/taskinstance.py", line 767, in _execute_task
    result = _execute_callable(context=context, **execute_callable_kwargs)
             ^^^^^^^^^^^^^^^^^^^^^^^^^^^^^^^^^^^^^^^^^^^^^^^^^^^^^^^^^^^^^
  File "/home/airflow/.local/lib/python3.12/site-packages/airflow/models/taskinstance.py", line 733, in _execute_callable
    return ExecutionCallableRunner(
           ^^^^^^^^^^^^^^^^^^^^^^^^
  File "/home/airflow/.local/lib/python3.12/site-packages/airflow/utils/operator_helpers.py", line 252, in run
    return self.func(*args, **kwargs)
           ^^^^^^^^^^^^^^^^^^^^^^^^^^
  File "/home/airflow/.local/lib/python3.12/site-packages/airflow/models/baseoperator.py", line 406, in wrapper
    return func(self, *args, **kwargs)
           ^^^^^^^^^^^^^^^^^^^^^^^^^^^
  File "/home/airflow/.local/lib/python3.12/site-packages/airflow/operators/python.py", line 238, in execute
    return_value = self.execute_callable()
                   ^^^^^^^^^^^^^^^^^^^^^^^
  File "/home/airflow/.local/lib/python3.12/site-packages/airflow/operators/python.py", line 256, in execute_callable
    return runner.run(*self.op_args, **self.op_kwargs)
           ^^^^^^^^^^^^^^^^^^^^^^^^^^^^^^^^^^^^^^^^^^^
  File "/home/airflow/.local/lib/python3.12/site-packages/airflow/utils/operator_helpers.py", line 252, in run
    return self.func(*args, **kwargs)
           ^^^^^^^^^^^^^^^^^^^^^^^^^^
  File "/opt/airflow/dags/spotify_airflow_pipeline.py", line 141, in _move_processed_data
    keys = s3_hook.list_keys(bucket=bucket_name, prefix=prefix)
           ^^^^^^^^^^^^^^^^^^^^^^^^^^^^^^^^^^^^^^^^^^^^^^^^^^^^
  File "/home/airflow/.local/lib/python3.12/site-packages/airflow/providers/amazon/aws/hooks/s3.py", line 115, in wrapper
    bound_args = function_signature.bind(*args, **kwargs)
                 ^^^^^^^^^^^^^^^^^^^^^^^^^^^^^^^^^^^^^^^^
  File "/usr/local/lib/python3.12/inspect.py", line 3273, in bind
    return self._bind(args, kwargs)
           ^^^^^^^^^^^^^^^^^^^^^^^^
  File "/usr/local/lib/python3.12/inspect.py", line 3262, in _bind
    raise TypeError(
TypeError: got an unexpected keyword argument 'bucket'
[2024-10-08T09:08:09.133+0000] {logging_mixin.py:190} INFO - Task instance in failure state
[2024-10-08T09:08:09.134+0000] {logging_mixin.py:190} INFO - Task start:2024-10-08 09:08:08.189921+00:00 end:2024-10-08 09:08:09.132628+00:00 duration:0.942707
[2024-10-08T09:08:09.134+0000] {logging_mixin.py:190} INFO - Task:<Task(PythonOperator): move_processed_data> dag:<DAG: spotify_etl_dag> dagrun:<DagRun spotify_etl_dag @ 2024-10-08 09:06:50.168917+00:00: manual__2024-10-08T09:06:50.168917+00:00, state:running, queued_at: 2024-10-08 09:06:50.226801+00:00. externally triggered: True>
[2024-10-08T09:08:09.135+0000] {logging_mixin.py:190} INFO - Failure caused by got an unexpected keyword argument 'bucket'
[2024-10-08T09:08:09.136+0000] {taskinstance.py:1225} INFO - Marking task as FAILED. dag_id=spotify_etl_dag, task_id=move_processed_data, run_id=manual__2024-10-08T09:06:50.168917+00:00, execution_date=20241008T090650, start_date=20241008T090808, end_date=20241008T090809
[2024-10-08T09:08:09.154+0000] {taskinstance.py:340} INFO - ::group::Post task execution logs
[2024-10-08T09:08:09.156+0000] {standard_task_runner.py:124} ERROR - Failed to execute job 445 for task move_processed_data (got an unexpected keyword argument 'bucket'; 894)
Traceback (most recent call last):
  File "/home/airflow/.local/lib/python3.12/site-packages/airflow/task/task_runner/standard_task_runner.py", line 117, in _start_by_fork
    ret = args.func(args, dag=self.dag)
          ^^^^^^^^^^^^^^^^^^^^^^^^^^^^^
  File "/home/airflow/.local/lib/python3.12/site-packages/airflow/cli/cli_config.py", line 49, in command
    return func(*args, **kwargs)
           ^^^^^^^^^^^^^^^^^^^^^
  File "/home/airflow/.local/lib/python3.12/site-packages/airflow/utils/cli.py", line 115, in wrapper
    return f(*args, **kwargs)
           ^^^^^^^^^^^^^^^^^^
  File "/home/airflow/.local/lib/python3.12/site-packages/airflow/cli/commands/task_command.py", line 483, in task_run
    task_return_code = _run_task_by_selected_method(args, _dag, ti)
                       ^^^^^^^^^^^^^^^^^^^^^^^^^^^^^^^^^^^^^^^^^^^^
  File "/home/airflow/.local/lib/python3.12/site-packages/airflow/cli/commands/task_command.py", line 256, in _run_task_by_selected_method
    return _run_raw_task(args, ti)
           ^^^^^^^^^^^^^^^^^^^^^^^
  File "/home/airflow/.local/lib/python3.12/site-packages/airflow/cli/commands/task_command.py", line 341, in _run_raw_task
    return ti._run_raw_task(
           ^^^^^^^^^^^^^^^^^
  File "/home/airflow/.local/lib/python3.12/site-packages/airflow/utils/session.py", line 97, in wrapper
    return func(*args, session=session, **kwargs)
           ^^^^^^^^^^^^^^^^^^^^^^^^^^^^^^^^^^^^^^
  File "/home/airflow/.local/lib/python3.12/site-packages/airflow/models/taskinstance.py", line 3004, in _run_raw_task
    return _run_raw_task(
           ^^^^^^^^^^^^^^
  File "/home/airflow/.local/lib/python3.12/site-packages/airflow/models/taskinstance.py", line 273, in _run_raw_task
    TaskInstance._execute_task_with_callbacks(
  File "/home/airflow/.local/lib/python3.12/site-packages/airflow/models/taskinstance.py", line 3158, in _execute_task_with_callbacks
    result = self._execute_task(context, task_orig)
             ^^^^^^^^^^^^^^^^^^^^^^^^^^^^^^^^^^^^^^
  File "/home/airflow/.local/lib/python3.12/site-packages/airflow/models/taskinstance.py", line 3182, in _execute_task
    return _execute_task(self, context, task_orig)
           ^^^^^^^^^^^^^^^^^^^^^^^^^^^^^^^^^^^^^^^
  File "/home/airflow/.local/lib/python3.12/site-packages/airflow/models/taskinstance.py", line 767, in _execute_task
    result = _execute_callable(context=context, **execute_callable_kwargs)
             ^^^^^^^^^^^^^^^^^^^^^^^^^^^^^^^^^^^^^^^^^^^^^^^^^^^^^^^^^^^^^
  File "/home/airflow/.local/lib/python3.12/site-packages/airflow/models/taskinstance.py", line 733, in _execute_callable
    return ExecutionCallableRunner(
           ^^^^^^^^^^^^^^^^^^^^^^^^
  File "/home/airflow/.local/lib/python3.12/site-packages/airflow/utils/operator_helpers.py", line 252, in run
    return self.func(*args, **kwargs)
           ^^^^^^^^^^^^^^^^^^^^^^^^^^
  File "/home/airflow/.local/lib/python3.12/site-packages/airflow/models/baseoperator.py", line 406, in wrapper
    return func(self, *args, **kwargs)
           ^^^^^^^^^^^^^^^^^^^^^^^^^^^
  File "/home/airflow/.local/lib/python3.12/site-packages/airflow/operators/python.py", line 238, in execute
    return_value = self.execute_callable()
                   ^^^^^^^^^^^^^^^^^^^^^^^
  File "/home/airflow/.local/lib/python3.12/site-packages/airflow/operators/python.py", line 256, in execute_callable
    return runner.run(*self.op_args, **self.op_kwargs)
           ^^^^^^^^^^^^^^^^^^^^^^^^^^^^^^^^^^^^^^^^^^^
  File "/home/airflow/.local/lib/python3.12/site-packages/airflow/utils/operator_helpers.py", line 252, in run
    return self.func(*args, **kwargs)
           ^^^^^^^^^^^^^^^^^^^^^^^^^^
  File "/opt/airflow/dags/spotify_airflow_pipeline.py", line 141, in _move_processed_data
    keys = s3_hook.list_keys(bucket=bucket_name, prefix=prefix)
           ^^^^^^^^^^^^^^^^^^^^^^^^^^^^^^^^^^^^^^^^^^^^^^^^^^^^
  File "/home/airflow/.local/lib/python3.12/site-packages/airflow/providers/amazon/aws/hooks/s3.py", line 115, in wrapper
    bound_args = function_signature.bind(*args, **kwargs)
                 ^^^^^^^^^^^^^^^^^^^^^^^^^^^^^^^^^^^^^^^^
  File "/usr/local/lib/python3.12/inspect.py", line 3273, in bind
    return self._bind(args, kwargs)
           ^^^^^^^^^^^^^^^^^^^^^^^^
  File "/usr/local/lib/python3.12/inspect.py", line 3262, in _bind
    raise TypeError(
TypeError: got an unexpected keyword argument 'bucket'
[2024-10-08T09:08:09.215+0000] {local_task_job_runner.py:266} INFO - Task exited with return code 1
[2024-10-08T09:08:09.296+0000] {taskinstance.py:3900} INFO - 0 downstream tasks scheduled from follow-on schedule check
[2024-10-08T09:08:09.299+0000] {local_task_job_runner.py:245} INFO - ::endgroup::
