[2024-12-03T00:20:25.595+0000] {local_task_job_runner.py:123} INFO - ::group::Pre task execution logs
[2024-12-03T00:20:25.611+0000] {taskinstance.py:2612} INFO - Dependencies all met for dep_context=non-requeueable deps ti=<TaskInstance: spotify_etl_dag.fetch_spotify_data scheduled__2024-12-02T00:00:00+00:00 [queued]>
[2024-12-03T00:20:25.615+0000] {taskinstance.py:2612} INFO - Dependencies all met for dep_context=requeueable deps ti=<TaskInstance: spotify_etl_dag.fetch_spotify_data scheduled__2024-12-02T00:00:00+00:00 [queued]>
[2024-12-03T00:20:25.615+0000] {taskinstance.py:2865} INFO - Starting attempt 1 of 1
[2024-12-03T00:20:25.632+0000] {taskinstance.py:2888} INFO - Executing <Task(PythonOperator): fetch_spotify_data> on 2024-12-02 00:00:00+00:00
[2024-12-03T00:20:25.655+0000] {standard_task_runner.py:104} INFO - Running: ['***', 'tasks', 'run', 'spotify_etl_dag', 'fetch_spotify_data', 'scheduled__2024-12-02T00:00:00+00:00', '--job-id', '512', '--raw', '--subdir', 'DAGS_FOLDER/spotify_***_pipeline.py', '--cfg-path', '/tmp/tmpmbwjmp4t']
[2024-12-03T00:20:25.657+0000] {standard_task_runner.py:105} INFO - Job 512: Subtask fetch_spotify_data
[2024-12-03T00:20:25.664+0000] {warnings.py:112} WARNING - /home/***/.local/lib/python3.12/site-packages/***/task/task_runner/standard_task_runner.py:70: DeprecationWarning: This process (pid=23300) is multi-threaded, use of fork() may lead to deadlocks in the child.
  pid = os.fork()

[2024-12-03T00:20:25.665+0000] {standard_task_runner.py:72} INFO - Started process 23302 to run task
[2024-12-03T00:20:25.949+0000] {task_command.py:467} INFO - Running <TaskInstance: spotify_etl_dag.fetch_spotify_data scheduled__2024-12-02T00:00:00+00:00 [running]> on host da4c4a711107
[2024-12-03T00:20:26.156+0000] {taskinstance.py:3131} INFO - Exporting env vars: AIRFLOW_CTX_DAG_OWNER='Artika' AIRFLOW_CTX_DAG_ID='spotify_etl_dag' AIRFLOW_CTX_TASK_ID='fetch_spotify_data' AIRFLOW_CTX_EXECUTION_DATE='2024-12-02T00:00:00+00:00' AIRFLOW_CTX_TRY_NUMBER='1' AIRFLOW_CTX_DAG_RUN_ID='scheduled__2024-12-02T00:00:00+00:00'
[2024-12-03T00:20:26.216+0000] {logging_mixin.py:190} INFO - Task instance is in running state
[2024-12-03T00:20:26.217+0000] {logging_mixin.py:190} INFO -  Previous state of the Task instance: queued
[2024-12-03T00:20:26.217+0000] {logging_mixin.py:190} INFO - Current task name:fetch_spotify_data state:running start_date:2024-12-03 00:20:25.612763+00:00
[2024-12-03T00:20:26.217+0000] {logging_mixin.py:190} INFO - Dag name:spotify_etl_dag and current dag run status:running
[2024-12-03T00:20:26.219+0000] {taskinstance.py:731} INFO - ::endgroup::
[2024-12-03T00:20:28.128+0000] {client.py:292} ERROR - HTTP Error for GET to https://api.spotify.com/v1/playlists/37i9dQZEVXbNG2KDcFcKOF/tracks with Params: {'limit': 100, 'offset': 0, 'fields': None, 'market': None, 'additional_types': 'track'} returned 404 due to Resource not found
[2024-12-03T00:20:28.137+0000] {taskinstance.py:3310} ERROR - Task failed with exception
Traceback (most recent call last):
  File "/home/airflow/.local/lib/python3.12/site-packages/spotipy/client.py", line 275, in _internal_call
    response.raise_for_status()
  File "/home/airflow/.local/lib/python3.12/site-packages/requests/models.py", line 1024, in raise_for_status
    raise HTTPError(http_error_msg, response=self)
requests.exceptions.HTTPError: 404 Client Error: Not Found for url: https://api.spotify.com/v1/playlists/37i9dQZEVXbNG2KDcFcKOF/tracks?limit=100&offset=0&additional_types=track

During handling of the above exception, another exception occurred:

Traceback (most recent call last):
  File "/home/airflow/.local/lib/python3.12/site-packages/airflow/models/taskinstance.py", line 767, in _execute_task
    result = _execute_callable(context=context, **execute_callable_kwargs)
             ^^^^^^^^^^^^^^^^^^^^^^^^^^^^^^^^^^^^^^^^^^^^^^^^^^^^^^^^^^^^^
  File "/home/airflow/.local/lib/python3.12/site-packages/airflow/models/taskinstance.py", line 733, in _execute_callable
    return ExecutionCallableRunner(
           ^^^^^^^^^^^^^^^^^^^^^^^^
  File "/home/airflow/.local/lib/python3.12/site-packages/airflow/utils/operator_helpers.py", line 252, in run
    return self.func(*args, **kwargs)
           ^^^^^^^^^^^^^^^^^^^^^^^^^^
  File "/home/airflow/.local/lib/python3.12/site-packages/airflow/models/baseoperator.py", line 406, in wrapper
    return func(self, *args, **kwargs)
           ^^^^^^^^^^^^^^^^^^^^^^^^^^^
  File "/home/airflow/.local/lib/python3.12/site-packages/airflow/operators/python.py", line 238, in execute
    return_value = self.execute_callable()
                   ^^^^^^^^^^^^^^^^^^^^^^^
  File "/home/airflow/.local/lib/python3.12/site-packages/airflow/operators/python.py", line 256, in execute_callable
    return runner.run(*self.op_args, **self.op_kwargs)
           ^^^^^^^^^^^^^^^^^^^^^^^^^^^^^^^^^^^^^^^^^^^
  File "/home/airflow/.local/lib/python3.12/site-packages/airflow/utils/operator_helpers.py", line 252, in run
    return self.func(*args, **kwargs)
           ^^^^^^^^^^^^^^^^^^^^^^^^^^
  File "/opt/airflow/dags/spotify_airflow_pipeline.py", line 33, in _fetch_spotify_data
    spotify_data = sp.playlist_tracks(playlist_URI)
                   ^^^^^^^^^^^^^^^^^^^^^^^^^^^^^^^^
  File "/home/airflow/.local/lib/python3.12/site-packages/spotipy/client.py", line 698, in playlist_tracks
    return self.playlist_items(playlist_id, fields, limit, offset,
           ^^^^^^^^^^^^^^^^^^^^^^^^^^^^^^^^^^^^^^^^^^^^^^^^^^^^^^^
  File "/home/airflow/.local/lib/python3.12/site-packages/spotipy/client.py", line 722, in playlist_items
    return self._get(
           ^^^^^^^^^^
  File "/home/airflow/.local/lib/python3.12/site-packages/spotipy/client.py", line 327, in _get
    return self._internal_call("GET", url, payload, kwargs)
           ^^^^^^^^^^^^^^^^^^^^^^^^^^^^^^^^^^^^^^^^^^^^^^^^
  File "/home/airflow/.local/lib/python3.12/site-packages/spotipy/client.py", line 297, in _internal_call
    raise SpotifyException(
spotipy.exceptions.SpotifyException: http status: 404, code:-1 - https://api.spotify.com/v1/playlists/37i9dQZEVXbNG2KDcFcKOF/tracks?limit=100&offset=0&additional_types=track:
 Resource not found, reason: None
[2024-12-03T00:20:28.185+0000] {logging_mixin.py:190} INFO - Task instance in failure state
[2024-12-03T00:20:28.186+0000] {logging_mixin.py:190} INFO - Task start:2024-12-03 00:20:25.612763+00:00 end:2024-12-03 00:20:28.176819+00:00 duration:2.564056
[2024-12-03T00:20:28.186+0000] {logging_mixin.py:190} INFO - Task:<Task(PythonOperator): fetch_spotify_data> dag:<DAG: spotify_etl_dag> dagrun:<DagRun spotify_etl_dag @ 2024-12-02 00:00:00+00:00: scheduled__2024-12-02T00:00:00+00:00, state:running, queued_at: 2024-12-03 00:20:16.353609+00:00. externally triggered: False>
[2024-12-03T00:20:28.186+0000] {logging_mixin.py:190} INFO - Failure caused by http status: 404, code:-1 - https://api.spotify.com/v1/playlists/37i9dQZEVXbNG2KDcFcKOF/tracks?limit=100&offset=0&additional_types=track:
 Resource not found, reason: None
[2024-12-03T00:20:28.186+0000] {taskinstance.py:1225} INFO - Marking task as FAILED. dag_id=spotify_etl_dag, task_id=fetch_spotify_data, run_id=scheduled__2024-12-02T00:00:00+00:00, execution_date=20241202T000000, start_date=20241203T002025, end_date=20241203T002028
[2024-12-03T00:20:28.215+0000] {taskinstance.py:340} INFO - ::group::Post task execution logs
[2024-12-03T00:20:28.216+0000] {standard_task_runner.py:124} ERROR - Failed to execute job 512 for task fetch_spotify_data (http status: 404, code:-1 - https://api.spotify.com/v1/playlists/37i9dQZEVXbNG2KDcFcKOF/tracks?limit=100&offset=0&additional_types=track:
 Resource not found, reason: None; 23302)
Traceback (most recent call last):
  File "/home/airflow/.local/lib/python3.12/site-packages/spotipy/client.py", line 275, in _internal_call
    response.raise_for_status()
  File "/home/airflow/.local/lib/python3.12/site-packages/requests/models.py", line 1024, in raise_for_status
    raise HTTPError(http_error_msg, response=self)
requests.exceptions.HTTPError: 404 Client Error: Not Found for url: https://api.spotify.com/v1/playlists/37i9dQZEVXbNG2KDcFcKOF/tracks?limit=100&offset=0&additional_types=track

During handling of the above exception, another exception occurred:

Traceback (most recent call last):
  File "/home/airflow/.local/lib/python3.12/site-packages/airflow/task/task_runner/standard_task_runner.py", line 117, in _start_by_fork
    ret = args.func(args, dag=self.dag)
          ^^^^^^^^^^^^^^^^^^^^^^^^^^^^^
  File "/home/airflow/.local/lib/python3.12/site-packages/airflow/cli/cli_config.py", line 49, in command
    return func(*args, **kwargs)
           ^^^^^^^^^^^^^^^^^^^^^
  File "/home/airflow/.local/lib/python3.12/site-packages/airflow/utils/cli.py", line 115, in wrapper
    return f(*args, **kwargs)
           ^^^^^^^^^^^^^^^^^^
  File "/home/airflow/.local/lib/python3.12/site-packages/airflow/cli/commands/task_command.py", line 483, in task_run
    task_return_code = _run_task_by_selected_method(args, _dag, ti)
                       ^^^^^^^^^^^^^^^^^^^^^^^^^^^^^^^^^^^^^^^^^^^^
  File "/home/airflow/.local/lib/python3.12/site-packages/airflow/cli/commands/task_command.py", line 256, in _run_task_by_selected_method
    return _run_raw_task(args, ti)
           ^^^^^^^^^^^^^^^^^^^^^^^
  File "/home/airflow/.local/lib/python3.12/site-packages/airflow/cli/commands/task_command.py", line 341, in _run_raw_task
    return ti._run_raw_task(
           ^^^^^^^^^^^^^^^^^
  File "/home/airflow/.local/lib/python3.12/site-packages/airflow/utils/session.py", line 97, in wrapper
    return func(*args, session=session, **kwargs)
           ^^^^^^^^^^^^^^^^^^^^^^^^^^^^^^^^^^^^^^
  File "/home/airflow/.local/lib/python3.12/site-packages/airflow/models/taskinstance.py", line 3004, in _run_raw_task
    return _run_raw_task(
           ^^^^^^^^^^^^^^
  File "/home/airflow/.local/lib/python3.12/site-packages/airflow/models/taskinstance.py", line 273, in _run_raw_task
    TaskInstance._execute_task_with_callbacks(
  File "/home/airflow/.local/lib/python3.12/site-packages/airflow/models/taskinstance.py", line 3158, in _execute_task_with_callbacks
    result = self._execute_task(context, task_orig)
             ^^^^^^^^^^^^^^^^^^^^^^^^^^^^^^^^^^^^^^
  File "/home/airflow/.local/lib/python3.12/site-packages/airflow/models/taskinstance.py", line 3182, in _execute_task
    return _execute_task(self, context, task_orig)
           ^^^^^^^^^^^^^^^^^^^^^^^^^^^^^^^^^^^^^^^
  File "/home/airflow/.local/lib/python3.12/site-packages/airflow/models/taskinstance.py", line 767, in _execute_task
    result = _execute_callable(context=context, **execute_callable_kwargs)
             ^^^^^^^^^^^^^^^^^^^^^^^^^^^^^^^^^^^^^^^^^^^^^^^^^^^^^^^^^^^^^
  File "/home/airflow/.local/lib/python3.12/site-packages/airflow/models/taskinstance.py", line 733, in _execute_callable
    return ExecutionCallableRunner(
           ^^^^^^^^^^^^^^^^^^^^^^^^
  File "/home/airflow/.local/lib/python3.12/site-packages/airflow/utils/operator_helpers.py", line 252, in run
    return self.func(*args, **kwargs)
           ^^^^^^^^^^^^^^^^^^^^^^^^^^
  File "/home/airflow/.local/lib/python3.12/site-packages/airflow/models/baseoperator.py", line 406, in wrapper
    return func(self, *args, **kwargs)
           ^^^^^^^^^^^^^^^^^^^^^^^^^^^
  File "/home/airflow/.local/lib/python3.12/site-packages/airflow/operators/python.py", line 238, in execute
    return_value = self.execute_callable()
                   ^^^^^^^^^^^^^^^^^^^^^^^
  File "/home/airflow/.local/lib/python3.12/site-packages/airflow/operators/python.py", line 256, in execute_callable
    return runner.run(*self.op_args, **self.op_kwargs)
           ^^^^^^^^^^^^^^^^^^^^^^^^^^^^^^^^^^^^^^^^^^^
  File "/home/airflow/.local/lib/python3.12/site-packages/airflow/utils/operator_helpers.py", line 252, in run
    return self.func(*args, **kwargs)
           ^^^^^^^^^^^^^^^^^^^^^^^^^^
  File "/opt/airflow/dags/spotify_airflow_pipeline.py", line 33, in _fetch_spotify_data
    spotify_data = sp.playlist_tracks(playlist_URI)
                   ^^^^^^^^^^^^^^^^^^^^^^^^^^^^^^^^
  File "/home/airflow/.local/lib/python3.12/site-packages/spotipy/client.py", line 698, in playlist_tracks
    return self.playlist_items(playlist_id, fields, limit, offset,
           ^^^^^^^^^^^^^^^^^^^^^^^^^^^^^^^^^^^^^^^^^^^^^^^^^^^^^^^
  File "/home/airflow/.local/lib/python3.12/site-packages/spotipy/client.py", line 722, in playlist_items
    return self._get(
           ^^^^^^^^^^
  File "/home/airflow/.local/lib/python3.12/site-packages/spotipy/client.py", line 327, in _get
    return self._internal_call("GET", url, payload, kwargs)
           ^^^^^^^^^^^^^^^^^^^^^^^^^^^^^^^^^^^^^^^^^^^^^^^^
  File "/home/airflow/.local/lib/python3.12/site-packages/spotipy/client.py", line 297, in _internal_call
    raise SpotifyException(
spotipy.exceptions.SpotifyException: http status: 404, code:-1 - https://api.spotify.com/v1/playlists/37i9dQZEVXbNG2KDcFcKOF/tracks?limit=100&offset=0&additional_types=track:
 Resource not found, reason: None
[2024-12-03T00:20:28.263+0000] {local_task_job_runner.py:266} INFO - Task exited with return code 1
[2024-12-03T00:20:28.305+0000] {taskinstance.py:3900} INFO - 0 downstream tasks scheduled from follow-on schedule check
[2024-12-03T00:20:28.310+0000] {local_task_job_runner.py:245} INFO - ::endgroup::
